<?xml version="1.0" ?><!-- =================================================================================== --><!-- |    This document was autogenerated by xacro from /workspace/DevEnv/jazzy_ws/src/install/grr_description/share/grr_description/urdf/robots/grreg.urdf.xacro | --><!-- |    EDITING THIS FILE BY HAND IS NOT RECOMMENDED                                 | --><!-- =================================================================================== --><robot name="bloodstone"><!-- Specify some standard inertial calculations https://en.wikipedia.org/wiki/List_of_moments_of_inertia --><!-- These make use of xacro's mathematical functionality --><material name="black"><color rgba="0.0 0.0 0.0 1.0"/></material><material name="blue"><color rgba="0.13725490196078433 0.43137254901960786 0.5882352941176471 1.0"/></material><material name="green"><color rgba="0.0 0.8 0.0 1.0"/></material><material name="grey"><color rgba="0.2 0.2 0.2 1.0"/></material><material name="yellow"><color rgba="1.0 0.8431372549019608 0.0 1"/></material><material name="orange"><color rgba="0.9529411764705882 0.5294117647058824 0.1843137254901961 1"/></material><material name="brown"><color rgba="0.8705882352941177 0.8117647058823529 0.7647058823529411 1.0"/></material><material name="red"><color rgba="0.8 0.0 0.0 1.0"/></material><material name="white"><color rgba="1.0 1.0 1.0 1.0"/></material><material name="silver"><color rgba="0.700 0.700 0.700 1.000"/></material><material name="aluminum"><color rgba="0.5 0.5 0.5 1"/></material><material name="plastic"><color rgba="0.1 0.1 0.1 1"/></material><material name="zed_mat"><color rgba="0.8 0.8 0.8 1.0"/></material><material name="zedm_mat"><color rgba="0 0 0 1.0"/></material><material name="zed2_mat"><color rgba="0.25 0.25 0.25 1.0"/></material><material name="zed2i_mat"><color rgba="0.25 0.25 0.25 1.0"/></material><material name="zedx_mat"><color rgba="0.25 0.25 0.25 1.0"/></material><material name="zedxm_mat"><color rgba="0.25 0.25 0.25 1.0"/></material><material name="virtual_mat"><color rgba="0.25 0.25 0.25 1.0"/></material><material name="zedxonegs_mat"><color rgba="0.25 0.25 0.25 1.0"/></material><material name="zedxone4k_mat"><color rgba="0.25 0.25 0.25 1.0"/></material><link name="base_link"/><link name="chassis_link"><inertial><origin rpy="0 0 0" xyz="0 0 0"/><mass value="2.45"/><inertia ixx="0.025954687500000004" ixy="0.0" ixz="0.0" iyy="0.0103359375" iyz="0.0" izz="0.028848750000000003"/></inertial><visual><origin rpy="0 0 3.141592653589793" xyz="0 0 0"/><geometry><mesh filename="package://grr_description/meshes/drivebase.stl" scale="1 1 1"/></geometry><!-- <material name="blue"/> --></visual><collision><origin rpy="0 0 0" xyz="0 0 0"/><geometry><box size="0.18 0.33 0.0675"/></geometry></collision></link><joint name="chassis_joint" type="fixed"><parent link="base_link"/><child link="chassis_link"/><origin rpy="0 0 0" xyz="0 0 0"/></joint><link name="front_left_mecanum_link"><inertial><origin rpy="0 1.5707963267948966 0" xyz="0 0 0"/><mass value="1.1360000000000001"/><inertia ixx="0.00042284766390000004" ixy="0.0" ixz="0.0" iyy="0.00042284766390000004" iyz="0.0" izz="0.0005117113278"/></inertial><visual><origin rpy="0 0 0" xyz="0 0 0"/><geometry><mesh filename="package://grr_description/meshes/mecanum_wheel_1.stl" scale="0.001 0.001 0.001"/></geometry><material name="orange"/></visual><collision><origin rpy="0 0 0" xyz="0 0 0"/><geometry><cylinder length="0.042" radius="0.030015"/></geometry></collision></link><joint name="front_left_mecanum_joint" type="continuous"><origin rpy="0 -1.5707963267948966 0" xyz="0.09 0.10075 0"/><parent link="chassis_link"/><child link="front_left_mecanum_link"/><axis xyz="0.0 1.0 0.0 "/></joint><!-- <xacro:if value="${number==1}">
    </xacro:if>
    <xacro:if value="${number==3}">
    </xacro:if>
    <xacro:if value="${number==5}">
    </xacro:if>
    <xacro:if value="${number==7}">
      <xacro:property name="roller_x_rot" value="${(sin(roller_radians) * (pi/4) * type_offset)+(1.831*pi/180)}" />
      <xacro:property name="roller_y_rot" value="${(cos(roller_radians) * (pi/4) * type_offset)+(3.095*pi/180)}" />
      <xacro:property name="roller_z_rot" value="${(5.395*pi/180)}"/>
    </xacro:if> --><link name="front_left_roller_0"><visual><origin rpy="0 0 -1.5707963267948966 " xyz="0 0 0"/><geometry><mesh filename="package://grr_description/meshes/mecanum_roller.stl" scale="0.001 0.001 0.001"/></geometry><material name="grey"/></visual><collision><origin rpy="0 0 0" xyz="0 0 0"/><geometry><mesh filename="package://grr_description/meshes/mecanum_roller.stl" scale="0.001 0.001 0.001"/></geometry></collision><inertial><origin rpy="0 0 0" xyz="0 0 0"/><mass value="0.07"/><inertia ixx="9.426025000000001e-06" ixy="0.0" ixz="0.0" iyy="9.426025000000001e-06" iyz="0.0" izz="1.9166000000000004e-06"/></inertial></link><joint name="front_left_roller_0_joint" type="continuous"><origin rpy="-0.0 0 -0.7853981633974483" xyz="0.0 0 0.030015"/><parent link="front_left_mecanum_link"/><child link="front_left_roller_0"/><axis xyz="0.0 0.0 1.0"/></joint><!-- <xacro:if value="${number==1}">
    </xacro:if>
    <xacro:if value="${number==3}">
    </xacro:if>
    <xacro:if value="${number==5}">
    </xacro:if>
    <xacro:if value="${number==7}">
      <xacro:property name="roller_x_rot" value="${(sin(roller_radians) * (pi/4) * type_offset)+(1.831*pi/180)}" />
      <xacro:property name="roller_y_rot" value="${(cos(roller_radians) * (pi/4) * type_offset)+(3.095*pi/180)}" />
      <xacro:property name="roller_z_rot" value="${(5.395*pi/180)}"/>
    </xacro:if> --><link name="front_left_roller_1"><visual><origin rpy="0 0 -1.5707963267948966 " xyz="0 0 0"/><geometry><mesh filename="package://grr_description/meshes/mecanum_roller.stl" scale="0.001 0.001 0.001"/></geometry><material name="grey"/></visual><collision><origin rpy="0 0 0" xyz="0 0 0"/><geometry><mesh filename="package://grr_description/meshes/mecanum_roller.stl" scale="0.001 0.001 0.001"/></geometry></collision><inertial><origin rpy="0 0 0" xyz="0 0 0"/><mass value="0.07"/><inertia ixx="9.426025000000001e-06" ixy="0.0" ixz="0.0" iyy="9.426025000000001e-06" iyz="0.0" izz="1.9166000000000004e-06"/></inertial></link><joint name="front_left_roller_1_joint" type="continuous"><origin rpy="-0.5553603672697958 0 -0.5553603672697958" xyz="0.02122381003731422 0 0.021223810037314224"/><parent link="front_left_mecanum_link"/><child link="front_left_roller_1"/><axis xyz="0.0 0.0 1.0"/></joint><!-- <xacro:if value="${number==1}">
    </xacro:if>
    <xacro:if value="${number==3}">
    </xacro:if>
    <xacro:if value="${number==5}">
    </xacro:if>
    <xacro:if value="${number==7}">
      <xacro:property name="roller_x_rot" value="${(sin(roller_radians) * (pi/4) * type_offset)+(1.831*pi/180)}" />
      <xacro:property name="roller_y_rot" value="${(cos(roller_radians) * (pi/4) * type_offset)+(3.095*pi/180)}" />
      <xacro:property name="roller_z_rot" value="${(5.395*pi/180)}"/>
    </xacro:if> --><link name="front_left_roller_2"><visual><origin rpy="0 0 -1.5707963267948966 " xyz="0 0 0"/><geometry><mesh filename="package://grr_description/meshes/mecanum_roller.stl" scale="0.001 0.001 0.001"/></geometry><material name="grey"/></visual><collision><origin rpy="0 0 0" xyz="0 0 0"/><geometry><mesh filename="package://grr_description/meshes/mecanum_roller.stl" scale="0.001 0.001 0.001"/></geometry></collision><inertial><origin rpy="0 0 0" xyz="0 0 0"/><mass value="0.07"/><inertia ixx="9.426025000000001e-06" ixy="0.0" ixz="0.0" iyy="9.426025000000001e-06" iyz="0.0" izz="1.9166000000000004e-06"/></inertial></link><joint name="front_left_roller_2_joint" type="continuous"><origin rpy="-0.7853981633974483 0 -4.8091767343044744e-17" xyz="0.030015 0 1.8378886838203904e-18"/><parent link="front_left_mecanum_link"/><child link="front_left_roller_2"/><axis xyz="0.0 0.0 1.0"/></joint><!-- <xacro:if value="${number==1}">
    </xacro:if>
    <xacro:if value="${number==3}">
    </xacro:if>
    <xacro:if value="${number==5}">
    </xacro:if>
    <xacro:if value="${number==7}">
      <xacro:property name="roller_x_rot" value="${(sin(roller_radians) * (pi/4) * type_offset)+(1.831*pi/180)}" />
      <xacro:property name="roller_y_rot" value="${(cos(roller_radians) * (pi/4) * type_offset)+(3.095*pi/180)}" />
      <xacro:property name="roller_z_rot" value="${(5.395*pi/180)}"/>
    </xacro:if> --><link name="front_left_roller_3"><visual><origin rpy="0 0 -1.5707963267948966 " xyz="0 0 0"/><geometry><mesh filename="package://grr_description/meshes/mecanum_roller.stl" scale="0.001 0.001 0.001"/></geometry><material name="grey"/></visual><collision><origin rpy="0 0 0" xyz="0 0 0"/><geometry><mesh filename="package://grr_description/meshes/mecanum_roller.stl" scale="0.001 0.001 0.001"/></geometry></collision><inertial><origin rpy="0 0 0" xyz="0 0 0"/><mass value="0.07"/><inertia ixx="9.426025000000001e-06" ixy="0.0" ixz="0.0" iyy="9.426025000000001e-06" iyz="0.0" izz="1.9166000000000004e-06"/></inertial></link><joint name="front_left_roller_3_joint" type="continuous"><origin rpy="-0.5553603672697958 0 0.5553603672697958" xyz="0.021223810037314224 0 -0.02122381003731422"/><parent link="front_left_mecanum_link"/><child link="front_left_roller_3"/><axis xyz="0.0 0.0 1.0"/></joint><!-- <xacro:if value="${number==1}">
    </xacro:if>
    <xacro:if value="${number==3}">
    </xacro:if>
    <xacro:if value="${number==5}">
    </xacro:if>
    <xacro:if value="${number==7}">
      <xacro:property name="roller_x_rot" value="${(sin(roller_radians) * (pi/4) * type_offset)+(1.831*pi/180)}" />
      <xacro:property name="roller_y_rot" value="${(cos(roller_radians) * (pi/4) * type_offset)+(3.095*pi/180)}" />
      <xacro:property name="roller_z_rot" value="${(5.395*pi/180)}"/>
    </xacro:if> --><link name="front_left_roller_4"><visual><origin rpy="0 0 -1.5707963267948966 " xyz="0 0 0"/><geometry><mesh filename="package://grr_description/meshes/mecanum_roller.stl" scale="0.001 0.001 0.001"/></geometry><material name="grey"/></visual><collision><origin rpy="0 0 0" xyz="0 0 0"/><geometry><mesh filename="package://grr_description/meshes/mecanum_roller.stl" scale="0.001 0.001 0.001"/></geometry></collision><inertial><origin rpy="0 0 0" xyz="0 0 0"/><mass value="0.07"/><inertia ixx="9.426025000000001e-06" ixy="0.0" ixz="0.0" iyy="9.426025000000001e-06" iyz="0.0" izz="1.9166000000000004e-06"/></inertial></link><joint name="front_left_roller_4_joint" type="continuous"><origin rpy="-9.618353468608949e-17 0 0.7853981633974483" xyz="3.675777367640781e-18 0 -0.030015"/><parent link="front_left_mecanum_link"/><child link="front_left_roller_4"/><axis xyz="0.0 0.0 1.0"/></joint><!-- <xacro:if value="${number==1}">
    </xacro:if>
    <xacro:if value="${number==3}">
    </xacro:if>
    <xacro:if value="${number==5}">
    </xacro:if>
    <xacro:if value="${number==7}">
      <xacro:property name="roller_x_rot" value="${(sin(roller_radians) * (pi/4) * type_offset)+(1.831*pi/180)}" />
      <xacro:property name="roller_y_rot" value="${(cos(roller_radians) * (pi/4) * type_offset)+(3.095*pi/180)}" />
      <xacro:property name="roller_z_rot" value="${(5.395*pi/180)}"/>
    </xacro:if> --><link name="front_left_roller_5"><visual><origin rpy="0 0 -1.5707963267948966 " xyz="0 0 0"/><geometry><mesh filename="package://grr_description/meshes/mecanum_roller.stl" scale="0.001 0.001 0.001"/></geometry><material name="grey"/></visual><collision><origin rpy="0 0 0" xyz="0 0 0"/><geometry><mesh filename="package://grr_description/meshes/mecanum_roller.stl" scale="0.001 0.001 0.001"/></geometry></collision><inertial><origin rpy="0 0 0" xyz="0 0 0"/><mass value="0.07"/><inertia ixx="9.426025000000001e-06" ixy="0.0" ixz="0.0" iyy="9.426025000000001e-06" iyz="0.0" izz="1.9166000000000004e-06"/></inertial></link><joint name="front_left_roller_5_joint" type="continuous"><origin rpy="0.5553603672697958 0 0.5553603672697959" xyz="-0.02122381003731422 0 -0.021223810037314227"/><parent link="front_left_mecanum_link"/><child link="front_left_roller_5"/><axis xyz="0.0 0.0 1.0"/></joint><!-- <xacro:if value="${number==1}">
    </xacro:if>
    <xacro:if value="${number==3}">
    </xacro:if>
    <xacro:if value="${number==5}">
    </xacro:if>
    <xacro:if value="${number==7}">
      <xacro:property name="roller_x_rot" value="${(sin(roller_radians) * (pi/4) * type_offset)+(1.831*pi/180)}" />
      <xacro:property name="roller_y_rot" value="${(cos(roller_radians) * (pi/4) * type_offset)+(3.095*pi/180)}" />
      <xacro:property name="roller_z_rot" value="${(5.395*pi/180)}"/>
    </xacro:if> --><link name="front_left_roller_6"><visual><origin rpy="0 0 -1.5707963267948966 " xyz="0 0 0"/><geometry><mesh filename="package://grr_description/meshes/mecanum_roller.stl" scale="0.001 0.001 0.001"/></geometry><material name="grey"/></visual><collision><origin rpy="0 0 0" xyz="0 0 0"/><geometry><mesh filename="package://grr_description/meshes/mecanum_roller.stl" scale="0.001 0.001 0.001"/></geometry></collision><inertial><origin rpy="0 0 0" xyz="0 0 0"/><mass value="0.07"/><inertia ixx="9.426025000000001e-06" ixy="0.0" ixz="0.0" iyy="9.426025000000001e-06" iyz="0.0" izz="1.9166000000000004e-06"/></inertial></link><joint name="front_left_roller_6_joint" type="continuous"><origin rpy="0.7853981633974483 0 1.4427530202913423e-16" xyz="-0.030015 0 -5.513666051461171e-18"/><parent link="front_left_mecanum_link"/><child link="front_left_roller_6"/><axis xyz="0.0 0.0 1.0"/></joint><!-- <xacro:if value="${number==1}">
    </xacro:if>
    <xacro:if value="${number==3}">
    </xacro:if>
    <xacro:if value="${number==5}">
    </xacro:if>
    <xacro:if value="${number==7}">
      <xacro:property name="roller_x_rot" value="${(sin(roller_radians) * (pi/4) * type_offset)+(1.831*pi/180)}" />
      <xacro:property name="roller_y_rot" value="${(cos(roller_radians) * (pi/4) * type_offset)+(3.095*pi/180)}" />
      <xacro:property name="roller_z_rot" value="${(5.395*pi/180)}"/>
    </xacro:if> --><link name="front_left_roller_7"><visual><origin rpy="0 0 -1.5707963267948966 " xyz="0 0 0"/><geometry><mesh filename="package://grr_description/meshes/mecanum_roller.stl" scale="0.001 0.001 0.001"/></geometry><material name="grey"/></visual><collision><origin rpy="0 0 0" xyz="0 0 0"/><geometry><mesh filename="package://grr_description/meshes/mecanum_roller.stl" scale="0.001 0.001 0.001"/></geometry></collision><inertial><origin rpy="0 0 0" xyz="0 0 0"/><mass value="0.07"/><inertia ixx="9.426025000000001e-06" ixy="0.0" ixz="0.0" iyy="9.426025000000001e-06" iyz="0.0" izz="1.9166000000000004e-06"/></inertial></link><joint name="front_left_roller_7_joint" type="continuous"><origin rpy="0.5553603672697959 0 -0.5553603672697957" xyz="-0.021223810037314227 0 0.02122381003731422"/><parent link="front_left_mecanum_link"/><child link="front_left_roller_7"/><axis xyz="0.0 0.0 1.0"/></joint><link name="rear_right_mecanum_link"><inertial><origin rpy="0 1.5707963267948966 0" xyz="0 0 0"/><mass value="1.1360000000000001"/><inertia ixx="0.00042284766390000004" ixy="0.0" ixz="0.0" iyy="0.00042284766390000004" iyz="0.0" izz="0.0005117113278"/></inertial><visual><origin rpy="0 0 0" xyz="0 0 0"/><geometry><mesh filename="package://grr_description/meshes/mecanum_wheel_1.stl" scale="0.001 0.001 0.001"/></geometry><material name="orange"/></visual><collision><origin rpy="0 0 0" xyz="0 0 0"/><geometry><cylinder length="0.042" radius="0.030015"/></geometry></collision></link><joint name="rear_right_mecanum_joint" type="continuous"><origin rpy="0 -1.5707963267948966 0" xyz="-0.09 -0.10075 0"/><parent link="chassis_link"/><child link="rear_right_mecanum_link"/><axis xyz="0.0 1.0 0.0 "/></joint><!-- <xacro:if value="${number==1}">
    </xacro:if>
    <xacro:if value="${number==3}">
    </xacro:if>
    <xacro:if value="${number==5}">
    </xacro:if>
    <xacro:if value="${number==7}">
      <xacro:property name="roller_x_rot" value="${(sin(roller_radians) * (pi/4) * type_offset)+(1.831*pi/180)}" />
      <xacro:property name="roller_y_rot" value="${(cos(roller_radians) * (pi/4) * type_offset)+(3.095*pi/180)}" />
      <xacro:property name="roller_z_rot" value="${(5.395*pi/180)}"/>
    </xacro:if> --><link name="rear_right_roller_0"><visual><origin rpy="0 0 -1.5707963267948966 " xyz="0 0 0"/><geometry><mesh filename="package://grr_description/meshes/mecanum_roller.stl" scale="0.001 0.001 0.001"/></geometry><material name="grey"/></visual><collision><origin rpy="0 0 0" xyz="0 0 0"/><geometry><mesh filename="package://grr_description/meshes/mecanum_roller.stl" scale="0.001 0.001 0.001"/></geometry></collision><inertial><origin rpy="0 0 0" xyz="0 0 0"/><mass value="0.07"/><inertia ixx="9.426025000000001e-06" ixy="0.0" ixz="0.0" iyy="9.426025000000001e-06" iyz="0.0" izz="1.9166000000000004e-06"/></inertial></link><joint name="rear_right_roller_0_joint" type="continuous"><origin rpy="-0.0 0 -0.7853981633974483" xyz="0.0 0 0.030015"/><parent link="rear_right_mecanum_link"/><child link="rear_right_roller_0"/><axis xyz="0.0 0.0 1.0"/></joint><!-- <xacro:if value="${number==1}">
    </xacro:if>
    <xacro:if value="${number==3}">
    </xacro:if>
    <xacro:if value="${number==5}">
    </xacro:if>
    <xacro:if value="${number==7}">
      <xacro:property name="roller_x_rot" value="${(sin(roller_radians) * (pi/4) * type_offset)+(1.831*pi/180)}" />
      <xacro:property name="roller_y_rot" value="${(cos(roller_radians) * (pi/4) * type_offset)+(3.095*pi/180)}" />
      <xacro:property name="roller_z_rot" value="${(5.395*pi/180)}"/>
    </xacro:if> --><link name="rear_right_roller_1"><visual><origin rpy="0 0 -1.5707963267948966 " xyz="0 0 0"/><geometry><mesh filename="package://grr_description/meshes/mecanum_roller.stl" scale="0.001 0.001 0.001"/></geometry><material name="grey"/></visual><collision><origin rpy="0 0 0" xyz="0 0 0"/><geometry><mesh filename="package://grr_description/meshes/mecanum_roller.stl" scale="0.001 0.001 0.001"/></geometry></collision><inertial><origin rpy="0 0 0" xyz="0 0 0"/><mass value="0.07"/><inertia ixx="9.426025000000001e-06" ixy="0.0" ixz="0.0" iyy="9.426025000000001e-06" iyz="0.0" izz="1.9166000000000004e-06"/></inertial></link><joint name="rear_right_roller_1_joint" type="continuous"><origin rpy="-0.5553603672697958 0 -0.5553603672697958" xyz="0.02122381003731422 0 0.021223810037314224"/><parent link="rear_right_mecanum_link"/><child link="rear_right_roller_1"/><axis xyz="0.0 0.0 1.0"/></joint><!-- <xacro:if value="${number==1}">
    </xacro:if>
    <xacro:if value="${number==3}">
    </xacro:if>
    <xacro:if value="${number==5}">
    </xacro:if>
    <xacro:if value="${number==7}">
      <xacro:property name="roller_x_rot" value="${(sin(roller_radians) * (pi/4) * type_offset)+(1.831*pi/180)}" />
      <xacro:property name="roller_y_rot" value="${(cos(roller_radians) * (pi/4) * type_offset)+(3.095*pi/180)}" />
      <xacro:property name="roller_z_rot" value="${(5.395*pi/180)}"/>
    </xacro:if> --><link name="rear_right_roller_2"><visual><origin rpy="0 0 -1.5707963267948966 " xyz="0 0 0"/><geometry><mesh filename="package://grr_description/meshes/mecanum_roller.stl" scale="0.001 0.001 0.001"/></geometry><material name="grey"/></visual><collision><origin rpy="0 0 0" xyz="0 0 0"/><geometry><mesh filename="package://grr_description/meshes/mecanum_roller.stl" scale="0.001 0.001 0.001"/></geometry></collision><inertial><origin rpy="0 0 0" xyz="0 0 0"/><mass value="0.07"/><inertia ixx="9.426025000000001e-06" ixy="0.0" ixz="0.0" iyy="9.426025000000001e-06" iyz="0.0" izz="1.9166000000000004e-06"/></inertial></link><joint name="rear_right_roller_2_joint" type="continuous"><origin rpy="-0.7853981633974483 0 -4.8091767343044744e-17" xyz="0.030015 0 1.8378886838203904e-18"/><parent link="rear_right_mecanum_link"/><child link="rear_right_roller_2"/><axis xyz="0.0 0.0 1.0"/></joint><!-- <xacro:if value="${number==1}">
    </xacro:if>
    <xacro:if value="${number==3}">
    </xacro:if>
    <xacro:if value="${number==5}">
    </xacro:if>
    <xacro:if value="${number==7}">
      <xacro:property name="roller_x_rot" value="${(sin(roller_radians) * (pi/4) * type_offset)+(1.831*pi/180)}" />
      <xacro:property name="roller_y_rot" value="${(cos(roller_radians) * (pi/4) * type_offset)+(3.095*pi/180)}" />
      <xacro:property name="roller_z_rot" value="${(5.395*pi/180)}"/>
    </xacro:if> --><link name="rear_right_roller_3"><visual><origin rpy="0 0 -1.5707963267948966 " xyz="0 0 0"/><geometry><mesh filename="package://grr_description/meshes/mecanum_roller.stl" scale="0.001 0.001 0.001"/></geometry><material name="grey"/></visual><collision><origin rpy="0 0 0" xyz="0 0 0"/><geometry><mesh filename="package://grr_description/meshes/mecanum_roller.stl" scale="0.001 0.001 0.001"/></geometry></collision><inertial><origin rpy="0 0 0" xyz="0 0 0"/><mass value="0.07"/><inertia ixx="9.426025000000001e-06" ixy="0.0" ixz="0.0" iyy="9.426025000000001e-06" iyz="0.0" izz="1.9166000000000004e-06"/></inertial></link><joint name="rear_right_roller_3_joint" type="continuous"><origin rpy="-0.5553603672697958 0 0.5553603672697958" xyz="0.021223810037314224 0 -0.02122381003731422"/><parent link="rear_right_mecanum_link"/><child link="rear_right_roller_3"/><axis xyz="0.0 0.0 1.0"/></joint><!-- <xacro:if value="${number==1}">
    </xacro:if>
    <xacro:if value="${number==3}">
    </xacro:if>
    <xacro:if value="${number==5}">
    </xacro:if>
    <xacro:if value="${number==7}">
      <xacro:property name="roller_x_rot" value="${(sin(roller_radians) * (pi/4) * type_offset)+(1.831*pi/180)}" />
      <xacro:property name="roller_y_rot" value="${(cos(roller_radians) * (pi/4) * type_offset)+(3.095*pi/180)}" />
      <xacro:property name="roller_z_rot" value="${(5.395*pi/180)}"/>
    </xacro:if> --><link name="rear_right_roller_4"><visual><origin rpy="0 0 -1.5707963267948966 " xyz="0 0 0"/><geometry><mesh filename="package://grr_description/meshes/mecanum_roller.stl" scale="0.001 0.001 0.001"/></geometry><material name="grey"/></visual><collision><origin rpy="0 0 0" xyz="0 0 0"/><geometry><mesh filename="package://grr_description/meshes/mecanum_roller.stl" scale="0.001 0.001 0.001"/></geometry></collision><inertial><origin rpy="0 0 0" xyz="0 0 0"/><mass value="0.07"/><inertia ixx="9.426025000000001e-06" ixy="0.0" ixz="0.0" iyy="9.426025000000001e-06" iyz="0.0" izz="1.9166000000000004e-06"/></inertial></link><joint name="rear_right_roller_4_joint" type="continuous"><origin rpy="-9.618353468608949e-17 0 0.7853981633974483" xyz="3.675777367640781e-18 0 -0.030015"/><parent link="rear_right_mecanum_link"/><child link="rear_right_roller_4"/><axis xyz="0.0 0.0 1.0"/></joint><!-- <xacro:if value="${number==1}">
    </xacro:if>
    <xacro:if value="${number==3}">
    </xacro:if>
    <xacro:if value="${number==5}">
    </xacro:if>
    <xacro:if value="${number==7}">
      <xacro:property name="roller_x_rot" value="${(sin(roller_radians) * (pi/4) * type_offset)+(1.831*pi/180)}" />
      <xacro:property name="roller_y_rot" value="${(cos(roller_radians) * (pi/4) * type_offset)+(3.095*pi/180)}" />
      <xacro:property name="roller_z_rot" value="${(5.395*pi/180)}"/>
    </xacro:if> --><link name="rear_right_roller_5"><visual><origin rpy="0 0 -1.5707963267948966 " xyz="0 0 0"/><geometry><mesh filename="package://grr_description/meshes/mecanum_roller.stl" scale="0.001 0.001 0.001"/></geometry><material name="grey"/></visual><collision><origin rpy="0 0 0" xyz="0 0 0"/><geometry><mesh filename="package://grr_description/meshes/mecanum_roller.stl" scale="0.001 0.001 0.001"/></geometry></collision><inertial><origin rpy="0 0 0" xyz="0 0 0"/><mass value="0.07"/><inertia ixx="9.426025000000001e-06" ixy="0.0" ixz="0.0" iyy="9.426025000000001e-06" iyz="0.0" izz="1.9166000000000004e-06"/></inertial></link><joint name="rear_right_roller_5_joint" type="continuous"><origin rpy="0.5553603672697958 0 0.5553603672697959" xyz="-0.02122381003731422 0 -0.021223810037314227"/><parent link="rear_right_mecanum_link"/><child link="rear_right_roller_5"/><axis xyz="0.0 0.0 1.0"/></joint><!-- <xacro:if value="${number==1}">
    </xacro:if>
    <xacro:if value="${number==3}">
    </xacro:if>
    <xacro:if value="${number==5}">
    </xacro:if>
    <xacro:if value="${number==7}">
      <xacro:property name="roller_x_rot" value="${(sin(roller_radians) * (pi/4) * type_offset)+(1.831*pi/180)}" />
      <xacro:property name="roller_y_rot" value="${(cos(roller_radians) * (pi/4) * type_offset)+(3.095*pi/180)}" />
      <xacro:property name="roller_z_rot" value="${(5.395*pi/180)}"/>
    </xacro:if> --><link name="rear_right_roller_6"><visual><origin rpy="0 0 -1.5707963267948966 " xyz="0 0 0"/><geometry><mesh filename="package://grr_description/meshes/mecanum_roller.stl" scale="0.001 0.001 0.001"/></geometry><material name="grey"/></visual><collision><origin rpy="0 0 0" xyz="0 0 0"/><geometry><mesh filename="package://grr_description/meshes/mecanum_roller.stl" scale="0.001 0.001 0.001"/></geometry></collision><inertial><origin rpy="0 0 0" xyz="0 0 0"/><mass value="0.07"/><inertia ixx="9.426025000000001e-06" ixy="0.0" ixz="0.0" iyy="9.426025000000001e-06" iyz="0.0" izz="1.9166000000000004e-06"/></inertial></link><joint name="rear_right_roller_6_joint" type="continuous"><origin rpy="0.7853981633974483 0 1.4427530202913423e-16" xyz="-0.030015 0 -5.513666051461171e-18"/><parent link="rear_right_mecanum_link"/><child link="rear_right_roller_6"/><axis xyz="0.0 0.0 1.0"/></joint><!-- <xacro:if value="${number==1}">
    </xacro:if>
    <xacro:if value="${number==3}">
    </xacro:if>
    <xacro:if value="${number==5}">
    </xacro:if>
    <xacro:if value="${number==7}">
      <xacro:property name="roller_x_rot" value="${(sin(roller_radians) * (pi/4) * type_offset)+(1.831*pi/180)}" />
      <xacro:property name="roller_y_rot" value="${(cos(roller_radians) * (pi/4) * type_offset)+(3.095*pi/180)}" />
      <xacro:property name="roller_z_rot" value="${(5.395*pi/180)}"/>
    </xacro:if> --><link name="rear_right_roller_7"><visual><origin rpy="0 0 -1.5707963267948966 " xyz="0 0 0"/><geometry><mesh filename="package://grr_description/meshes/mecanum_roller.stl" scale="0.001 0.001 0.001"/></geometry><material name="grey"/></visual><collision><origin rpy="0 0 0" xyz="0 0 0"/><geometry><mesh filename="package://grr_description/meshes/mecanum_roller.stl" scale="0.001 0.001 0.001"/></geometry></collision><inertial><origin rpy="0 0 0" xyz="0 0 0"/><mass value="0.07"/><inertia ixx="9.426025000000001e-06" ixy="0.0" ixz="0.0" iyy="9.426025000000001e-06" iyz="0.0" izz="1.9166000000000004e-06"/></inertial></link><joint name="rear_right_roller_7_joint" type="continuous"><origin rpy="0.5553603672697959 0 -0.5553603672697957" xyz="-0.021223810037314227 0 0.02122381003731422"/><parent link="rear_right_mecanum_link"/><child link="rear_right_roller_7"/><axis xyz="0.0 0.0 1.0"/></joint><link name="rear_left_mecanum_link"><inertial><origin rpy="0 1.5707963267948966 0" xyz="0 0 0"/><mass value="1.1360000000000001"/><inertia ixx="0.00042284766390000004" ixy="0.0" ixz="0.0" iyy="0.00042284766390000004" iyz="0.0" izz="0.0005117113278"/></inertial><visual><origin rpy="0 0 0" xyz="0 0 0"/><geometry><mesh filename="package://grr_description/meshes/mecanum_wheel_2.stl" scale="0.001 0.001 0.001"/></geometry><material name="orange"/></visual><collision><origin rpy="0 0 0" xyz="0 0 0"/><geometry><cylinder length="0.042" radius="0.030015"/></geometry></collision></link><joint name="rear_left_mecanum_joint" type="continuous"><origin rpy="0 -1.5707963267948966 0" xyz="-0.09 0.10075 0"/><parent link="chassis_link"/><child link="rear_left_mecanum_link"/><axis xyz="0.0 1.0 0.0 "/></joint><!-- <xacro:if value="${number==1}">
    </xacro:if>
    <xacro:if value="${number==3}">
    </xacro:if>
    <xacro:if value="${number==5}">
    </xacro:if>
    <xacro:if value="${number==7}">
      <xacro:property name="roller_x_rot" value="${(sin(roller_radians) * (pi/4) * type_offset)+(1.831*pi/180)}" />
      <xacro:property name="roller_y_rot" value="${(cos(roller_radians) * (pi/4) * type_offset)+(3.095*pi/180)}" />
      <xacro:property name="roller_z_rot" value="${(5.395*pi/180)}"/>
    </xacro:if> --><link name="rear_left_roller_0"><visual><origin rpy="0 0 -1.5707963267948966 " xyz="0 0 0"/><geometry><mesh filename="package://grr_description/meshes/mecanum_roller.stl" scale="0.001 0.001 0.001"/></geometry><material name="grey"/></visual><collision><origin rpy="0 0 0" xyz="0 0 0"/><geometry><mesh filename="package://grr_description/meshes/mecanum_roller.stl" scale="0.001 0.001 0.001"/></geometry></collision><inertial><origin rpy="0 0 0" xyz="0 0 0"/><mass value="0.07"/><inertia ixx="9.426025000000001e-06" ixy="0.0" ixz="0.0" iyy="9.426025000000001e-06" iyz="0.0" izz="1.9166000000000004e-06"/></inertial></link><joint name="rear_left_roller_0_joint" type="continuous"><origin rpy="0.0 0 0.7853981633974483" xyz="0.0 0 0.030015"/><parent link="rear_left_mecanum_link"/><child link="rear_left_roller_0"/><axis xyz="0.0 0.0 1.0"/></joint><!-- <xacro:if value="${number==1}">
    </xacro:if>
    <xacro:if value="${number==3}">
    </xacro:if>
    <xacro:if value="${number==5}">
    </xacro:if>
    <xacro:if value="${number==7}">
      <xacro:property name="roller_x_rot" value="${(sin(roller_radians) * (pi/4) * type_offset)+(1.831*pi/180)}" />
      <xacro:property name="roller_y_rot" value="${(cos(roller_radians) * (pi/4) * type_offset)+(3.095*pi/180)}" />
      <xacro:property name="roller_z_rot" value="${(5.395*pi/180)}"/>
    </xacro:if> --><link name="rear_left_roller_1"><visual><origin rpy="0 0 -1.5707963267948966 " xyz="0 0 0"/><geometry><mesh filename="package://grr_description/meshes/mecanum_roller.stl" scale="0.001 0.001 0.001"/></geometry><material name="grey"/></visual><collision><origin rpy="0 0 0" xyz="0 0 0"/><geometry><mesh filename="package://grr_description/meshes/mecanum_roller.stl" scale="0.001 0.001 0.001"/></geometry></collision><inertial><origin rpy="0 0 0" xyz="0 0 0"/><mass value="0.07"/><inertia ixx="9.426025000000001e-06" ixy="0.0" ixz="0.0" iyy="9.426025000000001e-06" iyz="0.0" izz="1.9166000000000004e-06"/></inertial></link><joint name="rear_left_roller_1_joint" type="continuous"><origin rpy="0.5553603672697958 0 0.5553603672697958" xyz="0.02122381003731422 0 0.021223810037314224"/><parent link="rear_left_mecanum_link"/><child link="rear_left_roller_1"/><axis xyz="0.0 0.0 1.0"/></joint><!-- <xacro:if value="${number==1}">
    </xacro:if>
    <xacro:if value="${number==3}">
    </xacro:if>
    <xacro:if value="${number==5}">
    </xacro:if>
    <xacro:if value="${number==7}">
      <xacro:property name="roller_x_rot" value="${(sin(roller_radians) * (pi/4) * type_offset)+(1.831*pi/180)}" />
      <xacro:property name="roller_y_rot" value="${(cos(roller_radians) * (pi/4) * type_offset)+(3.095*pi/180)}" />
      <xacro:property name="roller_z_rot" value="${(5.395*pi/180)}"/>
    </xacro:if> --><link name="rear_left_roller_2"><visual><origin rpy="0 0 -1.5707963267948966 " xyz="0 0 0"/><geometry><mesh filename="package://grr_description/meshes/mecanum_roller.stl" scale="0.001 0.001 0.001"/></geometry><material name="grey"/></visual><collision><origin rpy="0 0 0" xyz="0 0 0"/><geometry><mesh filename="package://grr_description/meshes/mecanum_roller.stl" scale="0.001 0.001 0.001"/></geometry></collision><inertial><origin rpy="0 0 0" xyz="0 0 0"/><mass value="0.07"/><inertia ixx="9.426025000000001e-06" ixy="0.0" ixz="0.0" iyy="9.426025000000001e-06" iyz="0.0" izz="1.9166000000000004e-06"/></inertial></link><joint name="rear_left_roller_2_joint" type="continuous"><origin rpy="0.7853981633974483 0 4.8091767343044744e-17" xyz="0.030015 0 1.8378886838203904e-18"/><parent link="rear_left_mecanum_link"/><child link="rear_left_roller_2"/><axis xyz="0.0 0.0 1.0"/></joint><!-- <xacro:if value="${number==1}">
    </xacro:if>
    <xacro:if value="${number==3}">
    </xacro:if>
    <xacro:if value="${number==5}">
    </xacro:if>
    <xacro:if value="${number==7}">
      <xacro:property name="roller_x_rot" value="${(sin(roller_radians) * (pi/4) * type_offset)+(1.831*pi/180)}" />
      <xacro:property name="roller_y_rot" value="${(cos(roller_radians) * (pi/4) * type_offset)+(3.095*pi/180)}" />
      <xacro:property name="roller_z_rot" value="${(5.395*pi/180)}"/>
    </xacro:if> --><link name="rear_left_roller_3"><visual><origin rpy="0 0 -1.5707963267948966 " xyz="0 0 0"/><geometry><mesh filename="package://grr_description/meshes/mecanum_roller.stl" scale="0.001 0.001 0.001"/></geometry><material name="grey"/></visual><collision><origin rpy="0 0 0" xyz="0 0 0"/><geometry><mesh filename="package://grr_description/meshes/mecanum_roller.stl" scale="0.001 0.001 0.001"/></geometry></collision><inertial><origin rpy="0 0 0" xyz="0 0 0"/><mass value="0.07"/><inertia ixx="9.426025000000001e-06" ixy="0.0" ixz="0.0" iyy="9.426025000000001e-06" iyz="0.0" izz="1.9166000000000004e-06"/></inertial></link><joint name="rear_left_roller_3_joint" type="continuous"><origin rpy="0.5553603672697958 0 -0.5553603672697958" xyz="0.021223810037314224 0 -0.02122381003731422"/><parent link="rear_left_mecanum_link"/><child link="rear_left_roller_3"/><axis xyz="0.0 0.0 1.0"/></joint><!-- <xacro:if value="${number==1}">
    </xacro:if>
    <xacro:if value="${number==3}">
    </xacro:if>
    <xacro:if value="${number==5}">
    </xacro:if>
    <xacro:if value="${number==7}">
      <xacro:property name="roller_x_rot" value="${(sin(roller_radians) * (pi/4) * type_offset)+(1.831*pi/180)}" />
      <xacro:property name="roller_y_rot" value="${(cos(roller_radians) * (pi/4) * type_offset)+(3.095*pi/180)}" />
      <xacro:property name="roller_z_rot" value="${(5.395*pi/180)}"/>
    </xacro:if> --><link name="rear_left_roller_4"><visual><origin rpy="0 0 -1.5707963267948966 " xyz="0 0 0"/><geometry><mesh filename="package://grr_description/meshes/mecanum_roller.stl" scale="0.001 0.001 0.001"/></geometry><material name="grey"/></visual><collision><origin rpy="0 0 0" xyz="0 0 0"/><geometry><mesh filename="package://grr_description/meshes/mecanum_roller.stl" scale="0.001 0.001 0.001"/></geometry></collision><inertial><origin rpy="0 0 0" xyz="0 0 0"/><mass value="0.07"/><inertia ixx="9.426025000000001e-06" ixy="0.0" ixz="0.0" iyy="9.426025000000001e-06" iyz="0.0" izz="1.9166000000000004e-06"/></inertial></link><joint name="rear_left_roller_4_joint" type="continuous"><origin rpy="9.618353468608949e-17 0 -0.7853981633974483" xyz="3.675777367640781e-18 0 -0.030015"/><parent link="rear_left_mecanum_link"/><child link="rear_left_roller_4"/><axis xyz="0.0 0.0 1.0"/></joint><!-- <xacro:if value="${number==1}">
    </xacro:if>
    <xacro:if value="${number==3}">
    </xacro:if>
    <xacro:if value="${number==5}">
    </xacro:if>
    <xacro:if value="${number==7}">
      <xacro:property name="roller_x_rot" value="${(sin(roller_radians) * (pi/4) * type_offset)+(1.831*pi/180)}" />
      <xacro:property name="roller_y_rot" value="${(cos(roller_radians) * (pi/4) * type_offset)+(3.095*pi/180)}" />
      <xacro:property name="roller_z_rot" value="${(5.395*pi/180)}"/>
    </xacro:if> --><link name="rear_left_roller_5"><visual><origin rpy="0 0 -1.5707963267948966 " xyz="0 0 0"/><geometry><mesh filename="package://grr_description/meshes/mecanum_roller.stl" scale="0.001 0.001 0.001"/></geometry><material name="grey"/></visual><collision><origin rpy="0 0 0" xyz="0 0 0"/><geometry><mesh filename="package://grr_description/meshes/mecanum_roller.stl" scale="0.001 0.001 0.001"/></geometry></collision><inertial><origin rpy="0 0 0" xyz="0 0 0"/><mass value="0.07"/><inertia ixx="9.426025000000001e-06" ixy="0.0" ixz="0.0" iyy="9.426025000000001e-06" iyz="0.0" izz="1.9166000000000004e-06"/></inertial></link><joint name="rear_left_roller_5_joint" type="continuous"><origin rpy="-0.5553603672697958 0 -0.5553603672697959" xyz="-0.02122381003731422 0 -0.021223810037314227"/><parent link="rear_left_mecanum_link"/><child link="rear_left_roller_5"/><axis xyz="0.0 0.0 1.0"/></joint><!-- <xacro:if value="${number==1}">
    </xacro:if>
    <xacro:if value="${number==3}">
    </xacro:if>
    <xacro:if value="${number==5}">
    </xacro:if>
    <xacro:if value="${number==7}">
      <xacro:property name="roller_x_rot" value="${(sin(roller_radians) * (pi/4) * type_offset)+(1.831*pi/180)}" />
      <xacro:property name="roller_y_rot" value="${(cos(roller_radians) * (pi/4) * type_offset)+(3.095*pi/180)}" />
      <xacro:property name="roller_z_rot" value="${(5.395*pi/180)}"/>
    </xacro:if> --><link name="rear_left_roller_6"><visual><origin rpy="0 0 -1.5707963267948966 " xyz="0 0 0"/><geometry><mesh filename="package://grr_description/meshes/mecanum_roller.stl" scale="0.001 0.001 0.001"/></geometry><material name="grey"/></visual><collision><origin rpy="0 0 0" xyz="0 0 0"/><geometry><mesh filename="package://grr_description/meshes/mecanum_roller.stl" scale="0.001 0.001 0.001"/></geometry></collision><inertial><origin rpy="0 0 0" xyz="0 0 0"/><mass value="0.07"/><inertia ixx="9.426025000000001e-06" ixy="0.0" ixz="0.0" iyy="9.426025000000001e-06" iyz="0.0" izz="1.9166000000000004e-06"/></inertial></link><joint name="rear_left_roller_6_joint" type="continuous"><origin rpy="-0.7853981633974483 0 -1.4427530202913423e-16" xyz="-0.030015 0 -5.513666051461171e-18"/><parent link="rear_left_mecanum_link"/><child link="rear_left_roller_6"/><axis xyz="0.0 0.0 1.0"/></joint><!-- <xacro:if value="${number==1}">
    </xacro:if>
    <xacro:if value="${number==3}">
    </xacro:if>
    <xacro:if value="${number==5}">
    </xacro:if>
    <xacro:if value="${number==7}">
      <xacro:property name="roller_x_rot" value="${(sin(roller_radians) * (pi/4) * type_offset)+(1.831*pi/180)}" />
      <xacro:property name="roller_y_rot" value="${(cos(roller_radians) * (pi/4) * type_offset)+(3.095*pi/180)}" />
      <xacro:property name="roller_z_rot" value="${(5.395*pi/180)}"/>
    </xacro:if> --><link name="rear_left_roller_7"><visual><origin rpy="0 0 -1.5707963267948966 " xyz="0 0 0"/><geometry><mesh filename="package://grr_description/meshes/mecanum_roller.stl" scale="0.001 0.001 0.001"/></geometry><material name="grey"/></visual><collision><origin rpy="0 0 0" xyz="0 0 0"/><geometry><mesh filename="package://grr_description/meshes/mecanum_roller.stl" scale="0.001 0.001 0.001"/></geometry></collision><inertial><origin rpy="0 0 0" xyz="0 0 0"/><mass value="0.07"/><inertia ixx="9.426025000000001e-06" ixy="0.0" ixz="0.0" iyy="9.426025000000001e-06" iyz="0.0" izz="1.9166000000000004e-06"/></inertial></link><joint name="rear_left_roller_7_joint" type="continuous"><origin rpy="-0.5553603672697959 0 0.5553603672697957" xyz="-0.021223810037314227 0 0.02122381003731422"/><parent link="rear_left_mecanum_link"/><child link="rear_left_roller_7"/><axis xyz="0.0 0.0 1.0"/></joint><link name="front_right_mecanum_link"><inertial><origin rpy="0 1.5707963267948966 0" xyz="0 0 0"/><mass value="1.1360000000000001"/><inertia ixx="0.00042284766390000004" ixy="0.0" ixz="0.0" iyy="0.00042284766390000004" iyz="0.0" izz="0.0005117113278"/></inertial><visual><origin rpy="0 0 0" xyz="0 0 0"/><geometry><mesh filename="package://grr_description/meshes/mecanum_wheel_2.stl" scale="0.001 0.001 0.001"/></geometry><material name="orange"/></visual><collision><origin rpy="0 0 0" xyz="0 0 0"/><geometry><cylinder length="0.042" radius="0.030015"/></geometry></collision></link><joint name="front_right_mecanum_joint" type="continuous"><origin rpy="0 -1.5707963267948966 0" xyz="0.09 -0.10075 0"/><parent link="chassis_link"/><child link="front_right_mecanum_link"/><axis xyz="0.0 1.0 0.0 "/></joint><!-- <xacro:if value="${number==1}">
    </xacro:if>
    <xacro:if value="${number==3}">
    </xacro:if>
    <xacro:if value="${number==5}">
    </xacro:if>
    <xacro:if value="${number==7}">
      <xacro:property name="roller_x_rot" value="${(sin(roller_radians) * (pi/4) * type_offset)+(1.831*pi/180)}" />
      <xacro:property name="roller_y_rot" value="${(cos(roller_radians) * (pi/4) * type_offset)+(3.095*pi/180)}" />
      <xacro:property name="roller_z_rot" value="${(5.395*pi/180)}"/>
    </xacro:if> --><link name="front_right_roller_0"><visual><origin rpy="0 0 -1.5707963267948966 " xyz="0 0 0"/><geometry><mesh filename="package://grr_description/meshes/mecanum_roller.stl" scale="0.001 0.001 0.001"/></geometry><material name="grey"/></visual><collision><origin rpy="0 0 0" xyz="0 0 0"/><geometry><mesh filename="package://grr_description/meshes/mecanum_roller.stl" scale="0.001 0.001 0.001"/></geometry></collision><inertial><origin rpy="0 0 0" xyz="0 0 0"/><mass value="0.07"/><inertia ixx="9.426025000000001e-06" ixy="0.0" ixz="0.0" iyy="9.426025000000001e-06" iyz="0.0" izz="1.9166000000000004e-06"/></inertial></link><joint name="front_right_roller_0_joint" type="continuous"><origin rpy="0.0 0 0.7853981633974483" xyz="0.0 0 0.030015"/><parent link="front_right_mecanum_link"/><child link="front_right_roller_0"/><axis xyz="0.0 0.0 1.0"/></joint><!-- <xacro:if value="${number==1}">
    </xacro:if>
    <xacro:if value="${number==3}">
    </xacro:if>
    <xacro:if value="${number==5}">
    </xacro:if>
    <xacro:if value="${number==7}">
      <xacro:property name="roller_x_rot" value="${(sin(roller_radians) * (pi/4) * type_offset)+(1.831*pi/180)}" />
      <xacro:property name="roller_y_rot" value="${(cos(roller_radians) * (pi/4) * type_offset)+(3.095*pi/180)}" />
      <xacro:property name="roller_z_rot" value="${(5.395*pi/180)}"/>
    </xacro:if> --><link name="front_right_roller_1"><visual><origin rpy="0 0 -1.5707963267948966 " xyz="0 0 0"/><geometry><mesh filename="package://grr_description/meshes/mecanum_roller.stl" scale="0.001 0.001 0.001"/></geometry><material name="grey"/></visual><collision><origin rpy="0 0 0" xyz="0 0 0"/><geometry><mesh filename="package://grr_description/meshes/mecanum_roller.stl" scale="0.001 0.001 0.001"/></geometry></collision><inertial><origin rpy="0 0 0" xyz="0 0 0"/><mass value="0.07"/><inertia ixx="9.426025000000001e-06" ixy="0.0" ixz="0.0" iyy="9.426025000000001e-06" iyz="0.0" izz="1.9166000000000004e-06"/></inertial></link><joint name="front_right_roller_1_joint" type="continuous"><origin rpy="0.5553603672697958 0 0.5553603672697958" xyz="0.02122381003731422 0 0.021223810037314224"/><parent link="front_right_mecanum_link"/><child link="front_right_roller_1"/><axis xyz="0.0 0.0 1.0"/></joint><!-- <xacro:if value="${number==1}">
    </xacro:if>
    <xacro:if value="${number==3}">
    </xacro:if>
    <xacro:if value="${number==5}">
    </xacro:if>
    <xacro:if value="${number==7}">
      <xacro:property name="roller_x_rot" value="${(sin(roller_radians) * (pi/4) * type_offset)+(1.831*pi/180)}" />
      <xacro:property name="roller_y_rot" value="${(cos(roller_radians) * (pi/4) * type_offset)+(3.095*pi/180)}" />
      <xacro:property name="roller_z_rot" value="${(5.395*pi/180)}"/>
    </xacro:if> --><link name="front_right_roller_2"><visual><origin rpy="0 0 -1.5707963267948966 " xyz="0 0 0"/><geometry><mesh filename="package://grr_description/meshes/mecanum_roller.stl" scale="0.001 0.001 0.001"/></geometry><material name="grey"/></visual><collision><origin rpy="0 0 0" xyz="0 0 0"/><geometry><mesh filename="package://grr_description/meshes/mecanum_roller.stl" scale="0.001 0.001 0.001"/></geometry></collision><inertial><origin rpy="0 0 0" xyz="0 0 0"/><mass value="0.07"/><inertia ixx="9.426025000000001e-06" ixy="0.0" ixz="0.0" iyy="9.426025000000001e-06" iyz="0.0" izz="1.9166000000000004e-06"/></inertial></link><joint name="front_right_roller_2_joint" type="continuous"><origin rpy="0.7853981633974483 0 4.8091767343044744e-17" xyz="0.030015 0 1.8378886838203904e-18"/><parent link="front_right_mecanum_link"/><child link="front_right_roller_2"/><axis xyz="0.0 0.0 1.0"/></joint><!-- <xacro:if value="${number==1}">
    </xacro:if>
    <xacro:if value="${number==3}">
    </xacro:if>
    <xacro:if value="${number==5}">
    </xacro:if>
    <xacro:if value="${number==7}">
      <xacro:property name="roller_x_rot" value="${(sin(roller_radians) * (pi/4) * type_offset)+(1.831*pi/180)}" />
      <xacro:property name="roller_y_rot" value="${(cos(roller_radians) * (pi/4) * type_offset)+(3.095*pi/180)}" />
      <xacro:property name="roller_z_rot" value="${(5.395*pi/180)}"/>
    </xacro:if> --><link name="front_right_roller_3"><visual><origin rpy="0 0 -1.5707963267948966 " xyz="0 0 0"/><geometry><mesh filename="package://grr_description/meshes/mecanum_roller.stl" scale="0.001 0.001 0.001"/></geometry><material name="grey"/></visual><collision><origin rpy="0 0 0" xyz="0 0 0"/><geometry><mesh filename="package://grr_description/meshes/mecanum_roller.stl" scale="0.001 0.001 0.001"/></geometry></collision><inertial><origin rpy="0 0 0" xyz="0 0 0"/><mass value="0.07"/><inertia ixx="9.426025000000001e-06" ixy="0.0" ixz="0.0" iyy="9.426025000000001e-06" iyz="0.0" izz="1.9166000000000004e-06"/></inertial></link><joint name="front_right_roller_3_joint" type="continuous"><origin rpy="0.5553603672697958 0 -0.5553603672697958" xyz="0.021223810037314224 0 -0.02122381003731422"/><parent link="front_right_mecanum_link"/><child link="front_right_roller_3"/><axis xyz="0.0 0.0 1.0"/></joint><!-- <xacro:if value="${number==1}">
    </xacro:if>
    <xacro:if value="${number==3}">
    </xacro:if>
    <xacro:if value="${number==5}">
    </xacro:if>
    <xacro:if value="${number==7}">
      <xacro:property name="roller_x_rot" value="${(sin(roller_radians) * (pi/4) * type_offset)+(1.831*pi/180)}" />
      <xacro:property name="roller_y_rot" value="${(cos(roller_radians) * (pi/4) * type_offset)+(3.095*pi/180)}" />
      <xacro:property name="roller_z_rot" value="${(5.395*pi/180)}"/>
    </xacro:if> --><link name="front_right_roller_4"><visual><origin rpy="0 0 -1.5707963267948966 " xyz="0 0 0"/><geometry><mesh filename="package://grr_description/meshes/mecanum_roller.stl" scale="0.001 0.001 0.001"/></geometry><material name="grey"/></visual><collision><origin rpy="0 0 0" xyz="0 0 0"/><geometry><mesh filename="package://grr_description/meshes/mecanum_roller.stl" scale="0.001 0.001 0.001"/></geometry></collision><inertial><origin rpy="0 0 0" xyz="0 0 0"/><mass value="0.07"/><inertia ixx="9.426025000000001e-06" ixy="0.0" ixz="0.0" iyy="9.426025000000001e-06" iyz="0.0" izz="1.9166000000000004e-06"/></inertial></link><joint name="front_right_roller_4_joint" type="continuous"><origin rpy="9.618353468608949e-17 0 -0.7853981633974483" xyz="3.675777367640781e-18 0 -0.030015"/><parent link="front_right_mecanum_link"/><child link="front_right_roller_4"/><axis xyz="0.0 0.0 1.0"/></joint><!-- <xacro:if value="${number==1}">
    </xacro:if>
    <xacro:if value="${number==3}">
    </xacro:if>
    <xacro:if value="${number==5}">
    </xacro:if>
    <xacro:if value="${number==7}">
      <xacro:property name="roller_x_rot" value="${(sin(roller_radians) * (pi/4) * type_offset)+(1.831*pi/180)}" />
      <xacro:property name="roller_y_rot" value="${(cos(roller_radians) * (pi/4) * type_offset)+(3.095*pi/180)}" />
      <xacro:property name="roller_z_rot" value="${(5.395*pi/180)}"/>
    </xacro:if> --><link name="front_right_roller_5"><visual><origin rpy="0 0 -1.5707963267948966 " xyz="0 0 0"/><geometry><mesh filename="package://grr_description/meshes/mecanum_roller.stl" scale="0.001 0.001 0.001"/></geometry><material name="grey"/></visual><collision><origin rpy="0 0 0" xyz="0 0 0"/><geometry><mesh filename="package://grr_description/meshes/mecanum_roller.stl" scale="0.001 0.001 0.001"/></geometry></collision><inertial><origin rpy="0 0 0" xyz="0 0 0"/><mass value="0.07"/><inertia ixx="9.426025000000001e-06" ixy="0.0" ixz="0.0" iyy="9.426025000000001e-06" iyz="0.0" izz="1.9166000000000004e-06"/></inertial></link><joint name="front_right_roller_5_joint" type="continuous"><origin rpy="-0.5553603672697958 0 -0.5553603672697959" xyz="-0.02122381003731422 0 -0.021223810037314227"/><parent link="front_right_mecanum_link"/><child link="front_right_roller_5"/><axis xyz="0.0 0.0 1.0"/></joint><!-- <xacro:if value="${number==1}">
    </xacro:if>
    <xacro:if value="${number==3}">
    </xacro:if>
    <xacro:if value="${number==5}">
    </xacro:if>
    <xacro:if value="${number==7}">
      <xacro:property name="roller_x_rot" value="${(sin(roller_radians) * (pi/4) * type_offset)+(1.831*pi/180)}" />
      <xacro:property name="roller_y_rot" value="${(cos(roller_radians) * (pi/4) * type_offset)+(3.095*pi/180)}" />
      <xacro:property name="roller_z_rot" value="${(5.395*pi/180)}"/>
    </xacro:if> --><link name="front_right_roller_6"><visual><origin rpy="0 0 -1.5707963267948966 " xyz="0 0 0"/><geometry><mesh filename="package://grr_description/meshes/mecanum_roller.stl" scale="0.001 0.001 0.001"/></geometry><material name="grey"/></visual><collision><origin rpy="0 0 0" xyz="0 0 0"/><geometry><mesh filename="package://grr_description/meshes/mecanum_roller.stl" scale="0.001 0.001 0.001"/></geometry></collision><inertial><origin rpy="0 0 0" xyz="0 0 0"/><mass value="0.07"/><inertia ixx="9.426025000000001e-06" ixy="0.0" ixz="0.0" iyy="9.426025000000001e-06" iyz="0.0" izz="1.9166000000000004e-06"/></inertial></link><joint name="front_right_roller_6_joint" type="continuous"><origin rpy="-0.7853981633974483 0 -1.4427530202913423e-16" xyz="-0.030015 0 -5.513666051461171e-18"/><parent link="front_right_mecanum_link"/><child link="front_right_roller_6"/><axis xyz="0.0 0.0 1.0"/></joint><!-- <xacro:if value="${number==1}">
    </xacro:if>
    <xacro:if value="${number==3}">
    </xacro:if>
    <xacro:if value="${number==5}">
    </xacro:if>
    <xacro:if value="${number==7}">
      <xacro:property name="roller_x_rot" value="${(sin(roller_radians) * (pi/4) * type_offset)+(1.831*pi/180)}" />
      <xacro:property name="roller_y_rot" value="${(cos(roller_radians) * (pi/4) * type_offset)+(3.095*pi/180)}" />
      <xacro:property name="roller_z_rot" value="${(5.395*pi/180)}"/>
    </xacro:if> --><link name="front_right_roller_7"><visual><origin rpy="0 0 -1.5707963267948966 " xyz="0 0 0"/><geometry><mesh filename="package://grr_description/meshes/mecanum_roller.stl" scale="0.001 0.001 0.001"/></geometry><material name="grey"/></visual><collision><origin rpy="0 0 0" xyz="0 0 0"/><geometry><mesh filename="package://grr_description/meshes/mecanum_roller.stl" scale="0.001 0.001 0.001"/></geometry></collision><inertial><origin rpy="0 0 0" xyz="0 0 0"/><mass value="0.07"/><inertia ixx="9.426025000000001e-06" ixy="0.0" ixz="0.0" iyy="9.426025000000001e-06" iyz="0.0" izz="1.9166000000000004e-06"/></inertial></link><joint name="front_right_roller_7_joint" type="continuous"><origin rpy="-0.5553603672697959 0 0.5553603672697957" xyz="-0.021223810037314227 0 0.02122381003731422"/><parent link="front_right_mecanum_link"/><child link="front_right_roller_7"/><axis xyz="0.0 0.0 1.0"/></joint><!-- <xacro:becan
    parent="base_link"
    origin="0 0 0"
  /> --><link name="intake_link"><visual><origin rpy="0 0 0" xyz="0 0 0"/><geometry><mesh filename="package://grr_description/meshes/intake.stl" scale="1 1 1"/></geometry><material name="yellow"/></visual><collision><origin rpy="0 0 0" xyz="0 0 0"/><geometry><box size="0.1 0.1 0.1"/></geometry></collision></link><joint name="intake_joint" type="fixed"><parent link="chassis_link"/><child link="intake_link"/><origin rpy="0 3.141592653589793 0" xyz="0.055 0.025 0.105"/></joint><link name="intake_roller_1_link"><visual><origin rpy="0 0 0" xyz="0 0 0"/><geometry><mesh filename="package://grr_description/meshes/intake_roller.stl" scale="1 1 1"/></geometry><material name="red"/></visual><collision><origin rpy="0 0 0" xyz="0 0 0"/><geometry><box size="0.1 0.1 0.1"/></geometry></collision></link><joint name="intake_roller_1_joint" type="continuous"><parent link="intake_link"/><child link="intake_roller_1_link"/><origin rpy="0 0 0" xyz="-0.0675 -0.05 -0.095"/><axis xyz="0 1 0"/></joint><link name="intake_roller_2_link"><visual><origin rpy="0 0 3.1415" xyz="0 0 0"/><geometry><mesh filename="package://grr_description/meshes/intake_roller.stl" scale="1 1 1"/></geometry><material name="red"/></visual><collision><origin rpy="0 0 0" xyz="0 0 0"/><geometry><box size="0.1 0.1 0.1"/></geometry></collision></link><joint name="intake_roller_2_joint" type="continuous"><parent link="intake_link"/><child link="intake_roller_2_link"/><origin rpy="0 0 0" xyz="-0.075 0.01 0.05"/><axis xyz="0 1 0"/></joint><link name="sorter_link"><visual><origin rpy="0 0 3.141592653589793" xyz="-0.025 0 0"/><geometry><mesh filename="package://grr_description/meshes/sorter_stand.stl" scale="1 1 1"/></geometry><material name="yellow"/></visual><collision><origin rpy="0 0 0" xyz="0 0 0"/><geometry><box size="0.1 0.1 0.1"/></geometry></collision></link><joint name="sorter_joint" type="fixed"><parent link="chassis_link"/><child link="sorter_link"/><origin rpy="0 0 0" xyz="-0.025 0 0.125"/></joint><link name="sorter_turntable_link"><visual><origin rpy="0 0 0" xyz="0 0 0"/><geometry><mesh filename="package://grr_description/meshes/sorter.stl" scale="1 1 1"/></geometry><material name="red"/></visual><collision><origin rpy="0 0 0" xyz="0 0 0"/><geometry><box size="0.1 0.1 0.1"/></geometry></collision></link><joint name="sorter_turntable_joint" type="continuous"><parent link="sorter_link"/><child link="sorter_turntable_link"/><origin rpy="0 -0.3490658503988659 0" xyz="-0.075 0 0.03"/><axis xyz="0 0 1"/></joint><link name="left_bin_grabber_base_link"><visual><origin rpy="0 0 -1.57075" xyz="0 0 0"/><geometry><mesh filename="package://grr_description/meshes/bingrableft_bottom.stl" scale="0.001 0.001 0.001"/></geometry><material name="yellow"/></visual><collision><origin rpy="0 0 0" xyz="0 0 0"/><geometry><box size="0.1 0.1 0.1"/></geometry></collision></link><joint name="left_bin_grabber_base_link" type="fixed"><parent link="chassis_link"/><child link="left_bin_grabber_base_link"/><origin rpy="0 0 0" xyz="-0.105 -0.085 0.065"/></joint><link name="left_bin_grabber_pivot_link"><visual><origin rpy="0 0 -1.5707963267948966" xyz="0 0 0"/><geometry><mesh filename="package://grr_description/meshes/bingrableft_middle.stl" scale="0.001 0.001 0.001"/></geometry><material name="red"/></visual><collision><origin rpy="0 0 0" xyz="0 0 0"/><geometry><box size="0.1 0.1 0.1"/></geometry></collision></link><joint name="left_bin_grabber_pivot_joint" type="revolute"><parent link="left_bin_grabber_base_link"/><child link="left_bin_grabber_pivot_link"/><origin rpy="0 0 0" xyz="0.0 0.005 0"/><axis xyz="0 1 0"/><limit effort="10" lower="-0.35" upper="0.044" velocity="0.5"/></joint><link name="left_bin_grabber_finger_link"><visual><origin rpy="0 0 3.141592653589793" xyz="0 0 0"/><geometry><mesh filename="package://grr_description/meshes/bingrableft_top.stl" scale="0.001 0.001 0.001"/></geometry><material name="blue"/></visual><collision><origin rpy="0 0 0" xyz="0 0 0"/><geometry><box size="0.1 0.1 0.1"/></geometry></collision></link><joint name="left_bin_grabber_finger_joint" type="revolute"><parent link="left_bin_grabber_pivot_link"/><child link="left_bin_grabber_finger_link"/><origin rpy="0 0 0" xyz="-0.01 0.002 0.06"/><axis xyz="0 -1 0"/><!-- add joint limits --><limit effort="10" lower="-3.14" upper="0.39" velocity="0.5"/></joint><link name="right_bin_grabber_base_link"><visual><origin rpy="0 0 1.57075" xyz="0 0 0"/><geometry><mesh filename="package://grr_description/meshes/bingrabright_bottom.stl" scale="0.001 0.001 0.001"/></geometry><material name="yellow"/></visual><collision><origin rpy="0 0 0" xyz="0 0 0"/><geometry><box size="0.1 0.1 0.1"/></geometry></collision></link><joint name="right_bin_grabber_base_link" type="fixed"><parent link="chassis_link"/><child link="right_bin_grabber_base_link"/><origin rpy="0 0 3.141592653589793" xyz="-0.105 0.085 0.065"/></joint><link name="right_bin_grabber_pivot_link"><visual><origin rpy="0 0 1.5707963267948966" xyz="0 0 0"/><geometry><mesh filename="package://grr_description/meshes/bingrabright_middle.stl" scale="0.001 0.001 0.001"/></geometry><material name="red"/></visual><collision><origin rpy="0 0 0" xyz="0 0 0"/><geometry><box size="0.1 0.1 0.1"/></geometry></collision></link><joint name="right_bin_grabber_pivot_joint" type="revolute"><parent link="right_bin_grabber_base_link"/><child link="right_bin_grabber_pivot_link"/><origin rpy="0 0 0" xyz="0.0 0.005 0"/><axis xyz="0 1 0"/><limit effort="10" lower="-0.35" upper="0.044" velocity="0.5"/></joint><link name="right_bin_grabber_finger_link"><visual><origin rpy="0 0 3.141592653589793" xyz="0 0 0"/><geometry><mesh filename="package://grr_description/meshes/bingrabright_top.stl" scale="0.001 0.001 0.001"/></geometry><material name="blue"/></visual><collision><origin rpy="0 0 0" xyz="0 0 0"/><geometry><box size="0.1 0.1 0.1"/></geometry></collision></link><joint name="right_bin_grabber_finger_joint" type="revolute"><parent link="right_bin_grabber_pivot_link"/><child link="right_bin_grabber_finger_link"/><origin rpy="0 0 0" xyz="0.01 0.002 0.06"/><axis xyz="0 1 0"/><!-- add joint limits --><limit effort="10" lower="-3.14" upper="0.39" velocity="0.5"/></joint><!-- Camera mounting point (the threaded screw hole in the bottom) --><link name="zed21_camera_link"/><joint name="zed21_camera_link_joint" type="fixed"><parent link="chassis_link"/><child link="zed21_camera_link"/><origin rpy="0.2617916666666667 1.57075 0" xyz="0 0 0"/></joint><!-- Camera Center --><link name="zed21_camera_center"><visual><origin rpy="0 0 0" xyz="-0.01 0 0.0"/><geometry><mesh filename="package://grr_description/meshes/zed2i.stl"/></geometry><material name="zed2i_mat"/></visual><collision><origin rpy="0 0 0" xyz="-0.01 0 0.0"/><geometry><mesh filename="package://grr_description/meshes/zed2i.stl"/></geometry></collision></link><joint name="zed21_camera_center_joint" type="fixed"><parent link="zed21_camera_link"/><child link="zed21_camera_center"/><origin rpy="0 0.0 0" xyz="0 0 0.015"/></joint><!-- Left Camera --><link name="zed21_left_camera_frame"></link><joint name="zed21_left_camera_joint" type="fixed"><parent link="zed21_camera_center"/><child link="zed21_left_camera_frame"/><origin rpy="0 0 0" xyz="-0.01 0.06 0"/></joint><link name="zed21_left_camera_optical_frame"/><joint name="zed21_left_camera_optical_joint" type="fixed"><origin rpy="0.0 1.5707963267948966 0.0" xyz="0 0 0"/><parent link="zed21_left_camera_frame"/><child link="zed21_left_camera_optical_frame"/></joint><!-- Right Camera --><link name="zed21_right_camera_frame"></link><joint name="zed21_right_camera_joint" type="fixed"><parent link="zed21_camera_center"/><child link="zed21_right_camera_frame"/><origin rpy="0 0 0" xyz="-0.01 -0.06 0"/></joint><link name="zed21_right_camera_optical_frame"/><joint name="zed21_right_camera_optical_joint" type="fixed"><origin rpy="0.0 1.5707963267948966 0.0" xyz="0 0 0"/><parent link="zed21_right_camera_frame"/><child link="zed21_right_camera_optical_frame"/></joint></robot>