<?xml version="1.0" ?>
<robot xmlns:xacro="http://www.ros.org/wiki/xacro">

<xacro:macro name="sorter" params="parent *origin">
    <link name="sorter_link">
        <visual>
        <origin xyz="-0.025 0 0" rpy="0 0 ${M_PI}"/>
        <geometry>
            <mesh filename="package://grr_description/meshes/sorter_stand.stl" scale="1 1 1"/>
        </geometry>
        <material name="yellow"/>
        </visual>
        <collision>
        <origin xyz="0 0 0" rpy="0 0 0"/>
        <geometry>
            <box size="0.1 0.1 0.1"/>
        </geometry>
        </collision>
    </link>
    <joint name="sorter_joint" type="fixed">
        <parent link="${parent}"/>
        <child link="sorter_link"/>
        <xacro:insert_block name="origin" />
    </joint>
    <link name="sorter_turntable_link">
        <visual>
        <origin xyz="0 0 0" rpy="0 0 0"/>
        <geometry>
            <mesh filename="package://grr_description/meshes/sorter.stl" scale="1 1 1"/>
        </geometry>
        <material name="red"/>
        </visual>
        <collision>
        <origin xyz="0 0 0" rpy="0 0 0"/>
        <geometry>
            <box size="0.1 0.1 0.1"/>
        </geometry>
        </collision>
    </link>
    <joint name="sorter_turntable_joint" type="continuous">
        <parent link="sorter_link"/>
        <child link="sorter_turntable_link"/>
        <origin xyz="-0.075 0 0.03" rpy="0 -${M_PI/9} 0"/>
        <axis xyz="0 0 1"/>
    </joint>
</xacro:macro>
</robot>